<?xml version="1.0"?>
<robot name="simple_arm">

  <link name="base_link">
    <visual>
      <geometry>
        <box size="0.2 0.2 0.05"/>
      </geometry>
      <origin xyz="0 0 0.025"/>
      <material name="gray"/>
    </visual>
  </link>

  <link name="link1">
    <visual>
      <geometry>
        <cylinder length="0.3" radius="0.03"/>
      </geometry>
      <origin xyz="0 0 0.15"/>
    </visual>
  </link>

  <joint name="joint1" type="revolute">
    <parent link="base_link"/>
    <child link="link1"/>
    <origin xyz="0 0 0.05" rpy="0 0 0"/>
    <axis xyz="0 0 1"/>
    <limit effort="1" lower="-3.14" upper="3.14" velocity="1.0"/>
  </joint>

  <link name="link2">
    <visual>
      <geometry>
        <cylinder length="0.25" radius="0.025"/>
      </geometry>
      <origin xyz="0 0 0.125"/>
    </visual>
  </link>

  <joint name="joint2" type="revolute">
    <parent link="link1"/>
    <child link="link2"/>
    <origin xyz="0 0 0.3" rpy="0 0 0"/>
    <axis xyz="0 1 0"/>
    <limit effort="1" lower="-3.14" upper="3.14" velocity="1.0"/>
  </joint>

</robot>