<?xml version="1.0"?>
<robot name="simple_robot">
    <link name="base_link">
        <visual>
            <geometry>
                <cylinder length="0.1" radius="0.1"/>
            </geometry>
            <material name="blue">
                <color rgba="0 0 0.8 1"/>
            </material>
        </visual>
        <collision>
            <geometry>
                <cylinder length="0.1" radius="0.1"/>
            </geometry>
        </collision>
        <inertial>
            <mass value="1"/>
            <inertia ixx="1" ixy="0" ixz="0" iyy="1" iyz="0" izz="1"/>
        </inertial>
    </link>

    <link name="link1">
        <visual>
            <geometry>
                <box size="0.1 0.1 0.5"/>
            </geometry>
            <material name="red">
                <color rgba="0.8 0 0 1"/>
            </material>
        </visual>
        <collision>
            <geometry>
                <box size="0.1 0.1 0.5"/>
            </geometry>
        </collision>
        <inertial>
            <mass value="1"/>
            <inertia ixx="1" ixy="0" ixz="0" iyy="1" iyz="0" izz="1"/>
        </inertial>
    </link>

    <link name="link2">
        <visual>
            <geometry>
                <box size="0.1 0.1 0.5"/>
            </geometry>
            <material name="green">
                <color rgba="0 0.8 0 1"/>
            </material>
        </visual>
        <collision>
            <geometry>
                <box size="0.1 0.1 0.5"/>
            </geometry>
        </collision>
        <inertial>
            <mass value="1"/>
            <inertia ixx="1" ixy="0" ixz="0" iyy="1" iyz="0" izz="1"/>
        </inertial>
    </link>

    <link name="link3">
        <visual>
            <geometry>
                <box size="0.1 0.1 0.5"/>
            </geometry>
            <material name="yellow">
                <color rgba="0.8 0.8 0 1"/>
            </material>
        </visual>
        <collision>
            <geometry>
                <box size="0.1 0.1 0.5"/>
            </geometry>
        </collision>
        <inertial>
            <mass value="1"/>
            <inertia ixx="1" ixy="0" ixz="0" iyy="1" iyz="0" izz="1"/>
        </inertial>
    </link>

    <joint name="joint1" type="revolute">
        <parent link="base_link"/>
        <child link="link1"/>
        <origin xyz="0 0 0.05"/>
        <axis xyz="0 0 1"/>
        <limit lower="-3.14159" upper="3.14159" effort="100" velocity="1"/>
    </joint>

    <joint name="joint2" type="revolute">
        <parent link="link1"/>
        <child link="link2"/>
        <origin xyz="0 0 0.25"/>
        <axis xyz="0 1 0"/>
        <limit lower="-3.14159" upper="3.14159" effort="100" velocity="1"/>
    </joint>

    <joint name="joint3" type="revolute">
        <parent link="link2"/>
        <child link="link3"/>
        <origin xyz="0 0 0.25"/>
        <axis xyz="0 1 0"/>
        <limit lower="-3.14159" upper="3.14159" effort="100" velocity="1"/>
    </joint>
</robot> 